Workbook

Sheet vo_1111
A1: ORDERNUMBER | B1: QUANTITYORDERED | C1: PRICEEACH | D1: ORDERLINENUMBER | E1: ORDERDATETIME | F1: DELIVERYDATETIME | G1: STATUS | H1: PRODUCTLINE | I1: CITY | J1: STATE | K1: POSTALCODE | L1: COUNTRY | M1: TERRITORY | N1: CONTACTLASTNAME | O1: CONTACTFIRSTNAME | P1: full name | Q1: full_name | R1: DEALSIZE | S1: len_text | T1: trim_text | U1: upper_text | V1: lower_text | W1: proper_text | X1: left_text | Y1: right_text | Z1: mid_text | AA1: mid_text2
A2: 10107 | B2: 30 | C2: 95.7 | D2: 2 | E2: 41623.035 | F2: 41625.381 | G2: Shipped | H2: Motorcycles | I2: NYC | J2: NY | K2: 10022 | L2: USA | M2: NA | N2: Yu | O2: Kwai | P2: =CONCATENATE(O2," ",N2) -> Kwai Yu | Q2: =O2&" "&N2 -> Kwai Yu | R2: Small | S2: =LEN(R2) -> 5 | T2: =TRIM(R2) -> Small | U2: =UPPER(T2) -> SMALL | V2: =LOWER(U2) -> small | W2: =PROPER(V2) -> Small | X2: =LEFT(A2,2) -> 10 | Y2: =RIGHT(A2,3) -> 107 | Z2: =MID(H2,6,6) -> cycles | AA2: =MID(G2,4,3) -> ppe
A3: 10121 | B3: 34 | C3: 81.35 | D3: 5 | E3: 41758.986 | F3: 41760.534 | G3: Shipped | H3: Motorcycles | I3: Reims | K3: 51100 | L3: France | M3: EMEA | N3: Henriot | O3: Paul | P3: =CONCATENATE(O3," ",N3) -> Paul Henriot | Q3: =O3&" "&N3 -> Paul Henriot | R3: Small | S3: =LEN(R3) -> 5 | T3: =TRIM(R3) -> Small | U3: =UPPER(T3) -> SMALL | V3: =LOWER(U3) -> small | W3: =PROPER(V3) -> Small | X3: =LEFT(A3,2) -> 10 | Y3: =RIGHT(A3,3) -> 121 | Z3: =MID(H3,6,6) -> cycles | AA3: =MID(G3,4,3) -> ppe
A4: 10134 | B4: 41 | C4: 94.74 | D4: 2 | E4: 41273.015 | F4: 41273.983 | G4: Shipped | H4: Motorcycles | I4: Paris | K4: 75508 | L4: France | M4: EMEA | N4: Da Cunha | O4: Daniel | P4: =CONCATENATE(O4," ",N4) -> Daniel Da Cunha | Q4: =O4&" "&N4 -> Daniel Da Cunha | R4: Medium | S4: =LEN(R4) -> 6 | T4: =TRIM(R4) -> Medium | U4: =UPPER(T4) -> MEDIUM | V4: =LOWER(U4) -> medium | W4: =PROPER(V4) -> Medium | X4: =LEFT(A4,2) -> 10 | Y4: =RIGHT(A4,3) -> 134 | Z4: =MID(H4,6,6) -> cycles | AA4: =MID(G4,4,3) -> ppe
A5: 10145 | B5: 45 | C5: 83.26 | D5: 6 | E5: 41971.022 | F5: 41972.256 | G5: Shipped | H5: Motorcycles | I5: Pasadena | J5: CA | K5: 90003 | L5: USA | M5: NA | N5: Young | O5: Julie | P5: =CONCATENATE(O5," ",N5) -> Julie Young | Q5: =O5&" "&N5 -> Julie Young | R5: Medium | S5: =LEN(R5) -> 6 | T5: =TRIM(R5) -> Medium | U5: =UPPER(T5) -> MEDIUM | V5: =LOWER(U5) -> medium | W5: =PROPER(V5) -> Medium | X5: =LEFT(A5,2) -> 10 | Y5: =RIGHT(A5,3) -> 145 | Z5: =MID(H5,6,6) -> cycles | AA5: =MID(G5,4,3) -> ppe
A6: 10159 | B6: 49 | C6: 100 | D6: 14 | E6: 41573.966 | F6: 41574.512 | G6: Shipped | H6: Motorcycles | I6: San Francisco | J6: CA | L6: USA | M6: NA | N6: Brown | O6: Julie | P6: =CONCATENATE(O6," ",N6) -> Julie Brown | Q6: =O6&" "&N6 -> Julie Brown | R6: Medium | S6: =LEN(R6) -> 6 | T6: =TRIM(R6) -> Medium | U6: =UPPER(T6) -> MEDIUM | V6: =LOWER(U6) -> medium | W6: =PROPER(V6) -> Medium | X6: =LEFT(A6,2) -> 10 | Y6: =RIGHT(A6,3) -> 159 | Z6: =MID(H6,6,6) -> cycles | AA6: =MID(G6,4,3) -> ppe
A7: 10168 | B7: 36 | C7: 96.66 | D7: 1 | E7: 42437.953 | F7: 42438.268 | G7: Shipped | H7: Motorcycles | I7: Burlingame | J7: CA | K7: 94217 | L7: USA | M7: NA | N7: Hirano | O7: Juri | P7: =CONCATENATE(O7," ",N7) -> Juri Hirano | Q7: =O7&" "&N7 -> Juri Hirano | R7: Medium | S7: =LEN(R7) -> 6 | T7: =TRIM(R7) -> Medium | U7: =UPPER(T7) -> MEDIUM | V7: =LOWER(U7) -> medium | W7: =PROPER(V7) -> Medium | X7: =LEFT(A7,2) -> 10 | Y7: =RIGHT(A7,3) -> 168 | Z7: =MID(H7,6,6) -> cycles | AA7: =MID(G7,4,3) -> ppe
A8: 10180 | B8: 29 | C8: 86.13 | D8: 9 | E8: 41688.016 | F8: 41688.798 | G8: Shipped | H8: Motorcycles | I8: Lille | K8: 59000 | L8: France | M8: EMEA | N8: Rance | O8: Martine | P8: =CONCATENATE(O8," ",N8) -> Martine Rance | Q8: =O8&" "&N8 -> Martine Rance | R8: Small | S8: =LEN(R8) -> 5 | T8: =TRIM(R8) -> Small | U8: =UPPER(T8) -> SMALL | V8: =LOWER(U8) -> small | W8: =PROPER(V8) -> Small | X8: =LEFT(A8,2) -> 10 | Y8: =RIGHT(A8,3) -> 180 | Z8: =MID(H8,6,6) -> cycles | AA8: =MID(G8,4,3) -> ppe
A9: 10188 | B9: 48 | C9: 100 | D9: 1 | E9: 41236.049 | F9: 41238.118 | G9: Shipped | H9: Motorcycles | I9: Bergen | K9: N 5804 | L9: Norway | M9: EMEA | N9: Oeztan | O9: Veysel | P9: =CONCATENATE(O9," ",N9) -> Veysel Oeztan | Q9: =O9&" "&N9 -> Veysel Oeztan | R9: Medium | S9: =LEN(R9) -> 6 | T9: =TRIM(R9) -> Medium | U9: =UPPER(T9) -> MEDIUM | V9: =LOWER(U9) -> medium | W9: =PROPER(V9) -> Medium | X9: =LEFT(A9,2) -> 10 | Y9: =RIGHT(A9,3) -> 188 | Z9: =MID(H9,6,6) -> cycles | AA9: =MID(G9,4,3) -> ppe
A10: 10201 | B10: 22 | C10: 98.57 | D10: 2 | E10: 41996.056 | F10: 41998.395 | G10: Shipped | H10: Motorcycles | I10: San Francisco | J10: CA | L10: USA | M10: NA | N10: Murphy | O10: Julie | P10: =CONCATENATE(O10," ",N10) -> Julie Murphy | Q10: =O10&" "&N10 -> Julie Murphy | R10: Small | S10: =LEN(R10) -> 5 | T10: =TRIM(R10) -> Small | U10: =UPPER(T10) -> SMALL | V10: =LOWER(U10) -> small | W10: =PROPER(V10) -> Small | X10: =LEFT(A10,2) -> 10 | Y10: =RIGHT(A10,3) -> 201 | Z10: =MID(H10,6,6) -> cycles | AA10: =MID(G10,4,3) -> ppe
A11: 10211 | B11: 41 | C11: 100 | D11: 14 | E11: 41216.99 | F11: 41219.944 | G11: Shipped | H11: Motorcycles | I11: Paris | K11: 75016 | L11: France | M11: EMEA | N11: Perrier | O11: Dominique | P11: =CONCATENATE(O11," ",N11) -> Dominique Perrier | Q11: =O11&" "&N11 -> Dominique Perrier | R11: Medium | S11: =LEN(R11) -> 6 | T11: =TRIM(R11) -> Medium | U11: =UPPER(T11) -> MEDIUM | V11: =LOWER(U11) -> medium | W11: =PROPER(V11) -> Medium | X11: =LEFT(A11,2) -> 10 | Y11: =RIGHT(A11,3) -> 211 | Z11: =MID(H11,6,6) -> cycles | AA11: =MID(G11,4,3) -> ppe
A12: 10223 | B12: 37 | C12: 100 | D12: 1 | E12: 41481.008 | F12: 41481.041 | G12: Shipped | H12: Motorcycles | I12: Melbourne | J12: Victoria | K12: 3004 | L12: Australia | M12: APAC | N12: Ferguson | O12: Peter | P12: =CONCATENATE(O12," ",N12) -> Peter Ferguson | Q12: =O12&" "&N12 -> Peter Ferguson | R12: Medium | S12: =LEN(R12) -> 6 | T12: =TRIM(R12) -> Medium | U12: =UPPER(T12) -> MEDIUM | V12: =LOWER(U12) -> medium | W12: =PROPER(V12) -> Medium | X12: =LEFT(A12,2) -> 10 | Y12: =RIGHT(A12,3) -> 223 | Z12: =MID(H12,6,6) -> cycles | AA12: =MID(G12,4,3) -> ppe
A13: 10237 | B13: 23 | C13: 100 | D13: 7 | E13: 41626.027 | F13: 41628.627 | G13: Shipped | H13: Motorcycles | I13: NYC | J13: NY | K13: 10022 | L13: USA | M13: NA | N13: Frick | O13: Michael | P13: =CONCATENATE(O13," ",N13) -> Michael Frick | Q13: =O13&" "&N13 -> Michael Frick | R13: Small | S13: =LEN(R13) -> 5 | T13: =TRIM(R13) -> Small | U13: =UPPER(T13) -> SMALL | V13: =LOWER(U13) -> small | W13: =PROPER(V13) -> Small | X13: =LEFT(A13,2) -> 10 | Y13: =RIGHT(A13,3) -> 237 | Z13: =MID(H13,6,6) -> cycles | AA13: =MID(G13,4,3) -> ppe
A14: 10251 | B14: 28 | C14: 100 | D14: 2 | E14: 41430.045 | F14: 41431.991 | G14: Shipped | H14: Motorcycles | I14: Newark | J14: NJ | K14: 94019 | L14: USA | M14: NA | N14: Brown | O14: William | P14: =CONCATENATE(O14," ",N14) -> William Brown | Q14: =O14&" "&N14 -> William Brown | R14: Medium | S14: =LEN(R14) -> 6 | T14: =TRIM(R14) -> Medium | U14: =UPPER(T14) -> MEDIUM | V14: =LOWER(U14) -> medium | W14: =PROPER(V14) -> Medium | X14: =LEFT(A14,2) -> 10 | Y14: =RIGHT(A14,3) -> 251 | Z14: =MID(H14,6,6) -> cycles | AA14: =MID(G14,4,3) -> ppe
A15: 10263 | B15: 34 | C15: 100 | D15: 2 | E15: 42701.937 | F15: 42702.929 | G15: Shipped | H15: Motorcycles | I15: Bridgewater | J15: CT | K15: 97562 | L15: USA | M15: NA | N15: King | O15: Julie | P15: =CONCATENATE(O15," ",N15) -> Julie King | Q15: =O15&" "&N15 -> Julie King | R15: Medium | S15: =LEN(R15) -> 6 | T15: =TRIM(R15) -> Medium | U15: =UPPER(T15) -> MEDIUM | V15: =LOWER(U15) -> medium | W15: =PROPER(V15) -> Medium | X15: =LEFT(A15,2) -> 10 | Y15: =RIGHT(A15,3) -> 263 | Z15: =MID(H15,6,6) -> cycles | AA15: =MID(G15,4,3) -> ppe
A16: 10275 | B16: 45 | C16: 92.83 | D16: 1 | E16: 42281.071 | F16: 42283.923 | G16: Shipped | H16: Motorcycles | I16: Nantes | K16: 44000 | L16: France | M16: EMEA | N16: Labrune | O16: Janine | P16: =CONCATENATE(O16," ",N16) -> Janine Labrune | Q16: =O16&" "&N16 -> Janine Labrune | R16: Medium | S16: =LEN(R16) -> 6 | T16: =TRIM(R16) -> Medium | U16: =UPPER(T16) -> MEDIUM | V16: =LOWER(U16) -> medium | W16: =PROPER(V16) -> Medium | X16: =LEFT(A16,2) -> 10 | Y16: =RIGHT(A16,3) -> 275 | Z16: =MID(H16,6,6) -> cycles | AA16: =MID(G16,4,3) -> ppe
A17: 10285 | B17: 36 | C17: 100 | D17: 6 | E17: 41145.967 | F17: 41147.999 | G17: Shipped | H17: Motorcycles | I17: Cambridge | J17: MA | K17: 51247 | L17: USA | M17: NA | N17: Hernandez | O17: Marta | P17: =CONCATENATE(O17," ",N17) -> Marta Hernandez | Q17: =O17&" "&N17 -> Marta Hernandez | R17: Medium | S17: =LEN(R17) -> 6 | T17: =TRIM(R17) -> Medium | U17: =UPPER(T17) -> MEDIUM | V17: =LOWER(U17) -> medium | W17: =PROPER(V17) -> Medium | X17: =LEFT(A17,2) -> 10 | Y17: =RIGHT(A17,3) -> 285 | Z17: =MID(H17,6,6) -> cycles | AA17: =MID(G17,4,3) -> ppe
A18: 10299 | B18: 23 | C18: 100 | D18: 9 | E18: 42296.953 | F18: 42297.525 | G18: Shipped | H18: Motorcycles | I18: Helsinki | K18: 21240 | L18: Finland | M18: EMEA | N18: Karttunen | O18: Matti | P18: =CONCATENATE(O18," ",N18) -> Matti Karttunen | Q18: =O18&" "&N18 -> Matti Karttunen | R18: Small | S18: =LEN(R18) -> 5 | T18: =TRIM(R18) -> Small | U18: =UPPER(T18) -> SMALL | V18: =LOWER(U18) -> small | W18: =PROPER(V18) -> Small | X18: =LEFT(A18,2) -> 10 | Y18: =RIGHT(A18,3) -> 299 | Z18: =MID(H18,6,6) -> cycles | AA18: =MID(G18,4,3) -> ppe
A19: 10309 | B19: 41 | C19: 100 | D19: 5 | E19: 41560.042 | F19: 41562.759 | G19: Shipped | H19: Motorcycles | I19: Stavern | K19: 4110 | L19: Norway | M19: EMEA | N19: Bergulfsen | O19: Jonas | P19: =CONCATENATE(O19," ",N19) -> Jonas Bergulfsen | Q19: =O19&" "&N19 -> Jonas Bergulfsen | R19: Medium | S19: =LEN(R19) -> 6 | T19: =TRIM(R19) -> Medium | U19: =UPPER(T19) -> MEDIUM | V19: =LOWER(U19) -> medium | W19: =PROPER(V19) -> Medium | X19: =LEFT(A19,2) -> 10 | Y19: =RIGHT(A19,3) -> 309 | Z19: =MID(H19,6,6) -> cycles | AA19: =MID(G19,4,3) -> ppe
A20: 10318 | B20: 46 | C20: 94.74 | D20: 1 | E20: 42388.94 | F20: 42390.231 | G20: Shipped | H20: Motorcycles | I20: Allentown | J20: PA | K20: 70267 | L20: USA | M20: NA | N20: Yu | O20: Kyung | P20: =CONCATENATE(O20," ",N20) -> Kyung Yu | Q20: =O20&" "&N20 -> Kyung Yu | R20: Medium | S20: =LEN(R20) -> 6 | T20: =TRIM(R20) -> Medium | U20: =UPPER(T20) -> MEDIUM | V20: =LOWER(U20) -> medium | W20: =PROPER(V20) -> Medium | X20: =LEFT(A20,2) -> 10 | Y20: =RIGHT(A20,3) -> 318 | Z20: =MID(H20,6,6) -> cycles | AA20: =MID(G20,4,3) -> ppe
A21: 10329 | B21: 42 | C21: 100 | D21: 1 | E21: 41715.969 | F21: 41717.956 | G21: Shipped | H21: Motorcycles | I21: NYC | J21: NY | K21: 10022 | L21: USA | M21: NA | N21: Yu | O21: Kwai | P21: =CONCATENATE(O21," ",N21) -> Kwai Yu | Q21: =O21&" "&N21 -> Kwai Yu | R21: Medium | S21: =LEN(R21) -> 6 | T21: =TRIM(R21) -> Medium | U21: =UPPER(T21) -> MEDIUM | V21: =LOWER(U21) -> medium | W21: =PROPER(V21) -> Medium | X21: =LEFT(A21,2) -> 10 | Y21: =RIGHT(A21,3) -> 329 | Z21: =MID(H21,6,6) -> cycles | AA21: =MID(G21,4,3) -> ppe
A22: 10341 | B22: 41 | C22: 100 | D22: 9 | E22: 41801.008 | F22: 41803.461 | G22: Shipped | H22: Motorcycles | I22: Salzburg | K22: 5020 | L22: Austria | M22: EMEA | N22: Pipps | O22: Georg | P22: =CONCATENATE(O22," ",N22) -> Georg Pipps | Q22: =O22&" "&N22 -> Georg Pipps | R22: Large | S22: =LEN(R22) -> 5 | T22: =TRIM(R22) -> Large | U22: =UPPER(T22) -> LARGE | V22: =LOWER(U22) -> large | W22: =PROPER(V22) -> Large | X22: =LEFT(A22,2) -> 10 | Y22: =RIGHT(A22,3) -> 341 | Z22: =MID(H22,6,6) -> cycles | AA22: =MID(G22,4,3) -> ppe
A23: 10361 | B23: 20 | C23: 72.55 | D23: 13 | E23: 41662.012 | F23: 41664.999 | G23: Shipped | H23: Motorcycles | I23: Chatswood | J23: NSW | K23: 2067 | L23: Australia | M23: APAC | N23: Huxley | O23: Adrian | P23: =CONCATENATE(O23," ",N23) -> Adrian Huxley | Q23: =O23&" "&N23 -> Adrian Huxley | R23: Small | S23: =LEN(R23) -> 5 | T23: =TRIM(R23) -> Small | U23: =UPPER(T23) -> SMALL | V23: =LOWER(U23) -> small | W23: =PROPER(V23) -> Small | X23: =LEFT(A23,2) -> 10 | Y23: =RIGHT(A23,3) -> 361 | Z23: =MID(H23,6,6) -> cycles | AA23: =MID(G23,4,3) -> ppe
A24: 10375 | B24: 21 | C24: 34.91 | D24: 12 | E24: 42053.024 | F24: 42053.126 | G24: Shipped | H24: Motorcycles | I24: Nantes | K24: 44000 | L24: France | M24: EMEA | N24: Labrune | O24: Janine | P24: =CONCATENATE(O24," ",N24) -> Janine Labrune | Q24: =O24&" "&N24 -> Janine Labrune | R24: Small | S24: =LEN(R24) -> 5 | T24: =TRIM(R24) -> Small | U24: =UPPER(T24) -> SMALL | V24: =LOWER(U24) -> small | W24: =PROPER(V24) -> Small | X24: =LEFT(A24,2) -> 10 | Y24: =RIGHT(A24,3) -> 375 | Z24: =MID(H24,6,6) -> cycles | AA24: =MID(G24,4,3) -> ppe
A25: 10388 | B25: 42 | C25: 76.36 | D25: 4 | E25: 41527.004 | F25: 41529.461 | G25: Shipped | H25: Motorcycles | I25: New Bedford | J25: MA | K25: 50553 | L25: USA | M25: NA | N25: Benitez | O25: Violeta | P25: =CONCATENATE(O25," ",N25) -> Violeta Benitez | Q25: =O25&" "&N25 -> Violeta Benitez | R25: Medium | S25: =LEN(R25) -> 6 | T25: =TRIM(R25) -> Medium | U25: =UPPER(T25) -> MEDIUM | V25: =LOWER(U25) -> medium | W25: =PROPER(V25) -> Medium | X25: =LEFT(A25,2) -> 10 | Y25: =RIGHT(A25,3) -> 388 | Z25: =MID(H25,6,6) -> cycles | AA25: =MID(G25,4,3) -> ppe
A26: 10403 | B26: 24 | C26: 100 | D26: 7 | E26: 41351.083 | F26: 41353.269 | G26: Shipped | H26: Motorcycles | I26: Liverpool | K26: WX1 6LT | L26: UK | M26: EMEA | N26: Devon | O26: Elizabeth | P26: =CONCATENATE(O26," ",N26) -> Elizabeth Devon | Q26: =O26&" "&N26 -> Elizabeth Devon | R26: Small | S26: =LEN(R26) -> 5 | T26: =TRIM(R26) -> Small | U26: =UPPER(T26) -> SMALL | V26: =LOWER(U26) -> small | W26: =PROPER(V26) -> Small | X26: =LEFT(A26,2) -> 10 | Y26: =RIGHT(A26,3) -> 403 | Z26: =MID(H26,6,6) -> cycles | AA26: =MID(G26,4,3) -> ppe
A27: 10417 | B27: 66 | C27: 100 | D27: 2 | E27: 41793.042 | F27: 41795.19 | G27: Disputed | H27: Motorcycles | I27: Madrid | K27: 28034 | L27: Spain | M27: EMEA | N27: Freyre | O27: Diego | P27: =CONCATENATE(O27," ",N27) -> Diego Freyre | Q27: =O27&" "&N27 -> Diego Freyre | R27: Large | S27: =LEN(R27) -> 5 | T27: =TRIM(R27) -> Large | U27: =UPPER(T27) -> LARGE | V27: =LOWER(U27) -> large | W27: =PROPER(V27) -> Large | X27: =LEFT(A27,2) -> 10 | Y27: =RIGHT(A27,3) -> 417 | Z27: =MID(H27,6,6) -> cycles | AA27: =MID(G27,4,3) -> put
A28: 10103 | B28: 26 | C28: 100 | D28: 11 | E28: 42582.972 | F28: 42585.098 | G28: Shipped | H28: Classic Cars | I28: Stavern | K28: 4110 | L28: Norway | M28: EMEA | N28: Bergulfsen | O28: Jonas | P28: =CONCATENATE(O28," ",N28) -> Jonas Bergulfsen | Q28: =O28&" "&N28 -> Jonas Bergulfsen | R28: Medium | S28: =LEN(R28) -> 6 | T28: =TRIM(R28) -> Medium | U28: =UPPER(T28) -> MEDIUM | V28: =LOWER(U28) -> medium | W28: =PROPER(V28) -> Medium | X28: =LEFT(A28,2) -> 10 | Y28: =RIGHT(A28,3) -> 103 | Z28: =MID(H28,6,6) -> ic Car | AA28: =MID(G28,4,3) -> ppe
A29: 10112 | B29: 29 | C29: 100 | D29: 1 | E29: 41973.958 | F29: 41975.813 | G29: Shipped | H29: Classic Cars | I29: Lule | K29: S-958 22 | L29: Sweden | M29: EMEA | N29: Berglund | O29: Christina | P29: =CONCATENATE(O29," ",N29) -> Christina Berglund | Q29: =O29&" "&N29 -> Christina Berglund | R29: Large | S29: =LEN(R29) -> 5 | T29: =TRIM(R29) -> Large | U29: =UPPER(T29) -> LARGE | V29: =LOWER(U29) -> large | W29: =PROPER(V29) -> Large | X29: =LEFT(A29,2) -> 10 | Y29: =RIGHT(A29,3) -> 112 | Z29: =MID(H29,6,6) -> ic Car | AA29: =MID(G29,4,3) -> ppe
A30: 10126 | B30: 38 | C30: 100 | D30: 11 | E30: 42682.012 | F30: 42682.66 | G30: Shipped | H30: Classic Cars | I30: Madrid | K30: 28023 | L30: Spain | M30: EMEA | N30: Sommer | O30: MartÂ¡n | P30: =CONCATENATE(O30," ",N30) -> MartÂ¡n Sommer | Q30: =O30&" "&N30 -> MartÂ¡n Sommer | R30: Large | S30: =LEN(R30) -> 5 | T30: =TRIM(R30) -> Large | U30: =UPPER(T30) -> LARGE | V30: =LOWER(U30) -> large | W30: =PROPER(V30) -> Large | X30: =LEFT(A30,2) -> 10 | Y30: =RIGHT(A30,3) -> 126 | Z30: =MID(H30,6,6) -> ic Car | AA30: =MID(G30,4,3) -> ppe
A31: 10140 | B31: 37 | C31: 100 | D31: 11 | E31: 41719.956 | F31: 41721.261 | G31: Shipped | H31: Classic Cars | I31: Burlingame | J31: CA | K31: 94217 | L31: USA | M31: NA | N31: Hirano | O31: Juri | P31: =CONCATENATE(O31," ",N31) -> Juri Hirano | Q31: =O31&" "&N31 -> Juri Hirano | R31: Large | S31: =LEN(R31) -> 5 | T31: =TRIM(R31) -> Large | U31: =UPPER(T31) -> LARGE | V31: =LOWER(U31) -> large | W31: =PROPER(V31) -> Large | X31: =LEFT(A31,2) -> 10 | Y31: =RIGHT(A31,3) -> 140 | Z31: =MID(H31,6,6) -> ic Car | AA31: =MID(G31,4,3) -> ppe
A32: 10150 | B32: 45 | C32: 100 | D32: 8 | E32: 41349.972 | F32: 41350.677 | G32: Shipped | H32: Classic Cars | I32: Singapore | K32: 79903 | L32: Singapore | M32: Japan | N32: Natividad | O32: Eric | P32: =CONCATENATE(O32," ",N32) -> Eric Natividad | Q32: =O32&" "&N32 -> Eric Natividad | R32: Large | S32: =LEN(R32) -> 5 | T32: =TRIM(R32) -> Large | U32: =UPPER(T32) -> LARGE | V32: =LOWER(U32) -> large | W32: =PROPER(V32) -> Large | X32: =LEFT(A32,2) -> 10 | Y32: =RIGHT(A32,3) -> 150 | Z32: =MID(H32,6,6) -> ic Car | AA32: =MID(G32,4,3) -> ppe
A33: 10163 | B33: 21 | C33: 100 | D33: 1 | E33: 41336.04 | F33: 41338.809 | G33: Shipped | H33: Classic Cars | I33: NYC | J33: NY | K33: 10022 | L33: USA | M33: NA | N33: Hernandez | O33: Maria | P33: =CONCATENATE(O33," ",N33) -> Maria Hernandez | Q33: =O33&" "&N33 -> Maria Hernandez | R33: Medium | S33: =LEN(R33) -> 6 | T33: =TRIM(R33) -> Medium | U33: =UPPER(T33) -> MEDIUM | V33: =LOWER(U33) -> medium | W33: =PROPER(V33) -> Medium | X33: =LEFT(A33,2) -> 10 | Y33: =RIGHT(A33,3) -> 163 | Z33: =MID(H33,6,6) -> ic Car | AA33: =MID(G33,4,3) -> ppe
A34: 10174 | B34: 34 | C34: 100 | D34: 4 | E34: 40959.986 | F34: 40960.349 | G34: Shipped | H34: Classic Cars | I34: South Brisbane | J34: Queensland | K34: 4101 | L34: Australia | M34: APAC | N34: Calaghan | O34: Tony | P34: =CONCATENATE(O34," ",N34) -> Tony Calaghan | Q34: =O34&" "&N34 -> Tony Calaghan | R34: Large | S34: =LEN(R34) -> 5 | T34: =TRIM(R34) -> Large | U34: =UPPER(T34) -> LARGE | V34: =LOWER(U34) -> large | W34: =PROPER(V34) -> Large | X34: =LEFT(A34,2) -> 10 | Y34: =RIGHT(A34,3) -> 174 | Z34: =MID(H34,6,6) -> ic Car | AA34: =MID(G34,4,3) -> ppe
A35: 10183 | B35: 23 | C35: 100 | D35: 8 | E35: 42188.031 | F35: 42189.155 | G35: Shipped | H35: Classic Cars | I35: Philadelphia | J35: PA | K35: 71270 | L35: USA | M35: NA | N35: Cervantes | O35: Francisca | P35: =CONCATENATE(O35," ",N35) -> Francisca Cervantes | Q35: =O35&" "&N35 -> Francisca Cervantes | R35: Medium | S35: =LEN(R35) -> 6 | T35: =TRIM(R35) -> Medium | U35: =UPPER(T35) -> MEDIUM | V35: =LOWER(U35) -> medium | W35: =PROPER(V35) -> Medium | X35: =LEFT(A35,2) -> 10 | Y35: =RIGHT(A35,3) -> 183 | Z35: =MID(H35,6,6) -> ic Car | AA35: =MID(G35,4,3) -> ppe
A36: 10194 | B36: 42 | C36: 100 | D36: 11 | E36: 42287.036 | F36: 42288.76 | G36: Shipped | H36: Classic Cars | I36: Lyon | K36: 69004 | L36: France | M36: EMEA | N36: Saveley | O36: Mary | P36: =CONCATENATE(O36," ",N36) -> Mary Saveley | Q36: =O36&" "&N36 -> Mary Saveley | R36: Large | S36: =LEN(R36) -> 5 | T36: =TRIM(R36) -> Large | U36: =UPPER(T36) -> LARGE | V36: =LOWER(U36) -> large | W36: =PROPER(V36) -> Large | X36: =LEFT(A36,2) -> 10 | Y36: =RIGHT(A36,3) -> 194 | Z36: =MID(H36,6,6) -> ic Car | AA36: =MID(G36,4,3) -> ppe
A37: 10206 | B37: 47 | C37: 100 | D37: 6 | E37: 42304.047 | F37: 42306.867 | G37: Shipped | H37: Classic Cars | I37: Vancouver | J37: BC | K37: V3F 2K1 | L37: Canada | M37: NA | N37: Tannamuri | O37: Yoshi | P37: =CONCATENATE(O37," ",N37) -> Yoshi Tannamuri | Q37: =O37&" "&N37 -> Yoshi Tannamuri | R37: Large | S37: =LEN(R37) -> 5 | T37: =TRIM(R37) -> Large | U37: =UPPER(T37) -> LARGE | V37: =LOWER(U37) -> large | W37: =PROPER(V37) -> Large | X37: =LEFT(A37,2) -> 10 | Y37: =RIGHT(A37,3) -> 206 | Z37: =MID(H37,6,6) -> ic Car | AA37: =MID(G37,4,3) -> ppe
A38: 10215 | B38: 35 | C38: 100 | D38: 3 | E38: 41820.051 | F38: 41822.995 | G38: Shipped | H38: Classic Cars | I38: Burbank | J38: CA | K38: 94019 | L38: USA | M38: NA | N38: Thompson | O38: Steve | P38: =CONCATENATE(O38," ",N38) -> Steve Thompson | Q38: =O38&" "&N38 -> Steve Thompson | R38: Medium | S38: =LEN(R38) -> 6 | T38: =TRIM(R38) -> Medium | U38: =UPPER(T38) -> MEDIUM | V38: =LOWER(U38) -> medium | W38: =PROPER(V38) -> Medium | X38: =LEFT(A38,2) -> 10 | Y38: =RIGHT(A38,3) -> 215 | Z38: =MID(H38,6,6) -> ic Car | AA38: =MID(G38,4,3) -> ppe
A39: 10228 | B39: 29 | C39: 100 | D39: 2 | E39: 41583.076 | F39: 41584.418 | G39: Shipped | H39: Classic Cars | I39: Cambridge | J39: MA | K39: 51247 | L39: USA | M39: NA | N39: Tseng | O39: Kyung | P39: =CONCATENATE(O39," ",N39) -> Kyung Tseng | Q39: =O39&" "&N39 -> Kyung Tseng | R39: Medium | S39: =LEN(R39) -> 6 | T39: =TRIM(R39) -> Medium | U39: =UPPER(T39) -> MEDIUM | V39: =LOWER(U39) -> medium | W39: =PROPER(V39) -> Medium | X39: =LEFT(A39,2) -> 10 | Y39: =RIGHT(A39,3) -> 228 | Z39: =MID(H39,6,6) -> ic Car | AA39: =MID(G39,4,3) -> ppe
A40: 10245 | B40: 34 | C40: 100 | D40: 9 | E40: 41573.008 | F40: 41574.497 | G40: Shipped | H40: Classic Cars | I40: New Haven | J40: CT | K40: 97823 | L40: USA | M40: NA | N40: Murphy | O40: Leslie | P40: =CONCATENATE(O40," ",N40) -> Leslie Murphy | Q40: =O40&" "&N40 -> Leslie Murphy | R40: Medium | S40: =LEN(R40) -> 6 | T40: =TRIM(R40) -> Medium | U40: =UPPER(T40) -> MEDIUM | V40: =LOWER(U40) -> medium | W40: =PROPER(V40) -> Medium | X40: =LEFT(A40,2) -> 10 | Y40: =RIGHT(A40,3) -> 245 | Z40: =MID(H40,6,6) -> ic Car | AA40: =MID(G40,4,3) -> ppe
...

Sheet sumif_avgif_countif
A1: PRODUCTLINE | B1: total quantity ordered | C1: average quantity ordered | D1: total no of orders | E1: PRODUCTLINE | F1: total quantity ordered | G1: average quantity ordered | H1: total no of orders
A2: Motorcycles | B2: =SUMIF(vo_1111!$H$2:$H$2824,sumif_avgif_countif!$A2,vo_1111!$B$2:$B$2824) -> 11663 | C2: =AVERAGEIF(vo_1111!$H$2:$H$2824,sumif_avgif_countif!$A2,vo_1111!$B$2:$B$2824) -> 35.23565 | D2: =COUNTIF(vo_1111!$H$2:$H$2824,sumif_avgif_countif!$A2) -> 331 | E2: Motorcycles | F2: =SUMIF(vo_1111!$H$2:$H$2824,sumif_avgif_countif!$E2,vo_1111!$B$2:$B$2824) -> 11663 | G2: =AVERAGEIF(vo_1111!$H$2:$H$2824,sumif_avgif_countif!$E2,vo_1111!$B$2:$B$2824) -> 35.23565 | H2: =COUNTIF(vo_1111!$H$2:$H$2824,sumif_avgif_countif!$E2) -> 331
A3: Classic Cars | B3: =SUMIF(vo_1111!$H$2:$H$2824,sumif_avgif_countif!$A3,vo_1111!$B$2:$B$2824) -> 33992 | C3: =AVERAGEIF(vo_1111!$H$2:$H$2824,sumif_avgif_countif!$A3,vo_1111!$B$2:$B$2824) -> 35.152017 | D3: =COUNTIF(vo_1111!$H$2:$H$2824,sumif_avgif_countif!$A3) -> 967 | E3: Classic Cars | F3: =SUMIF(vo_1111!$H$2:$H$2824,sumif_avgif_countif!$E3,vo_1111!$B$2:$B$2824) -> 33992 | G3: =AVERAGEIF(vo_1111!$H$2:$H$2824,sumif_avgif_countif!$E3,vo_1111!$B$2:$B$2824) -> 35.152017 | H3: =COUNTIF(vo_1111!$H$2:$H$2824,sumif_avgif_countif!$E3) -> 967
A4: Trucks and Buses | B4: =SUMIF(vo_1111!$H$2:$H$2824,sumif_avgif_countif!$A4,vo_1111!$B$2:$B$2824) -> 10777 | C4: =AVERAGEIF(vo_1111!$H$2:$H$2824,sumif_avgif_countif!$A4,vo_1111!$B$2:$B$2824) -> 35.803987 | D4: =COUNTIF(vo_1111!$H$2:$H$2824,sumif_avgif_countif!$A4) -> 301 | E4: Trucks and Buses | F4: =SUMIF(vo_1111!$H$2:$H$2824,sumif_avgif_countif!$E4,vo_1111!$B$2:$B$2824) -> 10777 | G4: =AVERAGEIF(vo_1111!$H$2:$H$2824,sumif_avgif_countif!$E4,vo_1111!$B$2:$B$2824) -> 35.803987 | H4: =COUNTIF(vo_1111!$H$2:$H$2824,sumif_avgif_countif!$E4) -> 301
A5: Vintage Cars | B5: =SUMIF(vo_1111!$H$2:$H$2824,sumif_avgif_countif!$A5,vo_1111!$B$2:$B$2824) -> 21069 | C5: =AVERAGEIF(vo_1111!$H$2:$H$2824,sumif_avgif_countif!$A5,vo_1111!$B$2:$B$2824) -> 34.710049 | D5: =COUNTIF(vo_1111!$H$2:$H$2824,sumif_avgif_countif!$A5) -> 607 | E5: Vintage Cars | F5: =SUMIF(vo_1111!$H$2:$H$2824,sumif_avgif_countif!$E5,vo_1111!$B$2:$B$2824) -> 21069 | G5: =AVERAGEIF(vo_1111!$H$2:$H$2824,sumif_avgif_countif!$E5,vo_1111!$B$2:$B$2824) -> 34.710049 | H5: =COUNTIF(vo_1111!$H$2:$H$2824,sumif_avgif_countif!$E5) -> 607
A6: Planes | B6: =SUMIF(vo_1111!$H$2:$H$2824,sumif_avgif_countif!$A6,vo_1111!$B$2:$B$2824) -> 10727 | C6: =AVERAGEIF(vo_1111!$H$2:$H$2824,sumif_avgif_countif!$A6,vo_1111!$B$2:$B$2824) -> 35.055556 | D6: =COUNTIF(vo_1111!$H$2:$H$2824,sumif_avgif_countif!$A6) -> 306 | E6: Planes | F6: =SUMIF(vo_1111!$H$2:$H$2824,sumif_avgif_countif!$E6,vo_1111!$B$2:$B$2824) -> 10727 | G6: =AVERAGEIF(vo_1111!$H$2:$H$2824,sumif_avgif_countif!$E6,vo_1111!$B$2:$B$2824) -> 35.055556 | H6: =COUNTIF(vo_1111!$H$2:$H$2824,sumif_avgif_countif!$E6) -> 306
A7: Ships | B7: =SUMIF(vo_1111!$H$2:$H$2824,sumif_avgif_countif!$A7,vo_1111!$B$2:$B$2824) -> 8127 | C7: =AVERAGEIF(vo_1111!$H$2:$H$2824,sumif_avgif_countif!$A7,vo_1111!$B$2:$B$2824) -> 34.730769 | D7: =COUNTIF(vo_1111!$H$2:$H$2824,sumif_avgif_countif!$A7) -> 234 | E7: Ships | F7: =SUMIF(vo_1111!$H$2:$H$2824,sumif_avgif_countif!$E7,vo_1111!$B$2:$B$2824) -> 8127 | G7: =AVERAGEIF(vo_1111!$H$2:$H$2824,sumif_avgif_countif!$E7,vo_1111!$B$2:$B$2824) -> 34.730769 | H7: =COUNTIF(vo_1111!$H$2:$H$2824,sumif_avgif_countif!$E7) -> 234
A8: Trains | B8: =SUMIF(vo_1111!$H$2:$H$2824,sumif_avgif_countif!$A8,vo_1111!$B$2:$B$2824) -> 2712 | C8: =AVERAGEIF(vo_1111!$H$2:$H$2824,sumif_avgif_countif!$A8,vo_1111!$B$2:$B$2824) -> 35.220779 | D8: =COUNTIF(vo_1111!$H$2:$H$2824,sumif_avgif_countif!$A8) -> 77 | E8: Trains | F8: =SUMIF(vo_1111!$H$2:$H$2824,sumif_avgif_countif!$E8,vo_1111!$B$2:$B$2824) -> 2712 | G8: =AVERAGEIF(vo_1111!$H$2:$H$2824,sumif_avgif_countif!$E8,vo_1111!$B$2:$B$2824) -> 35.220779 | H8: =COUNTIF(vo_1111!$H$2:$H$2824,sumif_avgif_countif!$E8) -> 77

Sheet sumif_countif_avgif
A1: DEALSIZE | B1: total qty | C1: avg qty | D1: total orders
A2: Small | B2: =SUMIF(vo_1111!$R$2:$R$2824,sumif_countif_avgif!$A2,vo_1111!$B$2:$B$2824) -> 39134 | C2: =AVERAGEIF(vo_1111!$R$2:$R$2824,sumif_countif_avgif!$A2,vo_1111!$B$2:$B$2824) -> 30.525741 | D2: =COUNTIF(vo_1111!$R$2:$R$2824,sumif_countif_avgif!$A2) -> 1282
A3: Medium | B3: =SUMIF(vo_1111!$R$2:$R$2824,sumif_countif_avgif!$A3,vo_1111!$B$2:$B$2824) -> 52519 | C3: =AVERAGEIF(vo_1111!$R$2:$R$2824,sumif_countif_avgif!$A3,vo_1111!$B$2:$B$2824) -> 37.947254 | D3: =COUNTIF(vo_1111!$R$2:$R$2824,sumif_countif_avgif!$A3) -> 1384
A4: Large | B4: =SUMIF(vo_1111!$R$2:$R$2824,sumif_countif_avgif!$A4,vo_1111!$B$2:$B$2824) -> 7414 | C4: =AVERAGEIF(vo_1111!$R$2:$R$2824,sumif_countif_avgif!$A4,vo_1111!$B$2:$B$2824) -> 47.22293 | D4: =COUNTIF(vo_1111!$R$2:$R$2824,sumif_countif_avgif!$A4) -> 157

Sheet ifs
A1: DEALSIZE | B1: PRODUCTLINE | C1: total qty | D1: avg qty | E1: count orders | F1: PRODUCTLINE | G1: DEALSIZE | H1: total qty | I1: avg qty | J1: cnt orders
A2: Small | B2: Motorcycles | C2: =SUMIFS(vo_1111!$B$2:$B$2824,vo_1111!$R$2:$R$2824,ifs!$A2,vo_1111!$H$2:$H$2824,ifs!$B2) -> 4818 | D2: =AVERAGEIFS(vo_1111!$B$2:$B$2824,vo_1111!$R$2:$R$2824,ifs!$A2,vo_1111!$H$2:$H$2824,ifs!$B2) -> 30.884615 | E2: =COUNTIFS(vo_1111!$R$2:$R$2824,ifs!$A2,vo_1111!$H$2:$H$2824,ifs!$B2) -> 156 | F2: Motorcycles | G2: Small | H2: =SUMIFS(vo_1111!$B$2:$B$2824,vo_1111!$H$2:$H$2824,ifs!$F2,vo_1111!$R$2:$R$2824,ifs!$G2) -> 4818 | I2: =AVERAGEIFS(vo_1111!$B$2:$B$2824,vo_1111!$H$2:$H$2824,ifs!$F2,vo_1111!$R$2:$R$2824,ifs!$G2) -> 30.884615 | J2: =COUNTIFS(vo_1111!$H$2:$H$2824,ifs!$F2,vo_1111!$R$2:$R$2824,ifs!$G2) -> 156 | M2: deal size | N2: productline
A3: Medium | B3: Motorcycles | C3: =SUMIFS(vo_1111!$B$2:$B$2824,vo_1111!$R$2:$R$2824,ifs!$A3,vo_1111!$H$2:$H$2824,ifs!$B3) -> 5929 | D3: =AVERAGEIFS(vo_1111!$B$2:$B$2824,vo_1111!$R$2:$R$2824,ifs!$A3,vo_1111!$H$2:$H$2824,ifs!$B3) -> 38.00641 | E3: =COUNTIFS(vo_1111!$R$2:$R$2824,ifs!$A3,vo_1111!$H$2:$H$2824,ifs!$B3) -> 156 | F3: Motorcycles | G3: Medium | H3: =SUMIFS(vo_1111!$B$2:$B$2824,vo_1111!$H$2:$H$2824,ifs!$F3,vo_1111!$R$2:$R$2824,ifs!$G3) -> 5929 | I3: =AVERAGEIFS(vo_1111!$B$2:$B$2824,vo_1111!$H$2:$H$2824,ifs!$F3,vo_1111!$R$2:$R$2824,ifs!$G3) -> 38.00641 | J3: =COUNTIFS(vo_1111!$H$2:$H$2824,ifs!$F3,vo_1111!$R$2:$R$2824,ifs!$G3) -> 156 | M3: 3 | N3: 7
A4: Large | B4: Motorcycles | C4: =SUMIFS(vo_1111!$B$2:$B$2824,vo_1111!$R$2:$R$2824,ifs!$A4,vo_1111!$H$2:$H$2824,ifs!$B4) -> 916 | D4: =AVERAGEIFS(vo_1111!$B$2:$B$2824,vo_1111!$R$2:$R$2824,ifs!$A4,vo_1111!$H$2:$H$2824,ifs!$B4) -> 48.210526 | E4: =COUNTIFS(vo_1111!$R$2:$R$2824,ifs!$A4,vo_1111!$H$2:$H$2824,ifs!$B4) -> 19 | F4: Motorcycles | G4: Large | H4: =SUMIFS(vo_1111!$B$2:$B$2824,vo_1111!$H$2:$H$2824,ifs!$F4,vo_1111!$R$2:$R$2824,ifs!$G4) -> 916 | I4: =AVERAGEIFS(vo_1111!$B$2:$B$2824,vo_1111!$H$2:$H$2824,ifs!$F4,vo_1111!$R$2:$R$2824,ifs!$G4) -> 48.210526 | J4: =COUNTIFS(vo_1111!$H$2:$H$2824,ifs!$F4,vo_1111!$R$2:$R$2824,ifs!$G4) -> 19 | L4: total combs | M4: =M3*N3 -> 21
A5: Medium | B5: Classic Cars | C5: =SUMIFS(vo_1111!$B$2:$B$2824,vo_1111!$R$2:$R$2824,ifs!$A5,vo_1111!$H$2:$H$2824,ifs!$B5) -> 19178 | D5: =AVERAGEIFS(vo_1111!$B$2:$B$2824,vo_1111!$R$2:$R$2824,ifs!$A5,vo_1111!$H$2:$H$2824,ifs!$B5) -> 36.184906 | E5: =COUNTIFS(vo_1111!$R$2:$R$2824,ifs!$A5,vo_1111!$H$2:$H$2824,ifs!$B5) -> 530 | F5: Classic Cars | G5: Medium | H5: =SUMIFS(vo_1111!$B$2:$B$2824,vo_1111!$H$2:$H$2824,ifs!$F5,vo_1111!$R$2:$R$2824,ifs!$G5) -> 19178 | I5: =AVERAGEIFS(vo_1111!$B$2:$B$2824,vo_1111!$H$2:$H$2824,ifs!$F5,vo_1111!$R$2:$R$2824,ifs!$G5) -> 36.184906 | J5: =COUNTIFS(vo_1111!$H$2:$H$2824,ifs!$F5,vo_1111!$R$2:$R$2824,ifs!$G5) -> 530
A6: Large | B6: Classic Cars | C6: =SUMIFS(vo_1111!$B$2:$B$2824,vo_1111!$R$2:$R$2824,ifs!$A6,vo_1111!$H$2:$H$2824,ifs!$B6) -> 4506 | D6: =AVERAGEIFS(vo_1111!$B$2:$B$2824,vo_1111!$R$2:$R$2824,ifs!$A6,vo_1111!$H$2:$H$2824,ifs!$B6) -> 46.453608 | E6: =COUNTIFS(vo_1111!$R$2:$R$2824,ifs!$A6,vo_1111!$H$2:$H$2824,ifs!$B6) -> 97 | F6: Classic Cars | G6: Large | H6: =SUMIFS(vo_1111!$B$2:$B$2824,vo_1111!$H$2:$H$2824,ifs!$F6,vo_1111!$R$2:$R$2824,ifs!$G6) -> 4506 | I6: =AVERAGEIFS(vo_1111!$B$2:$B$2824,vo_1111!$H$2:$H$2824,ifs!$F6,vo_1111!$R$2:$R$2824,ifs!$G6) -> 46.453608 | J6: =COUNTIFS(vo_1111!$H$2:$H$2824,ifs!$F6,vo_1111!$R$2:$R$2824,ifs!$G6) -> 97
A7: Small | B7: Classic Cars | C7: =SUMIFS(vo_1111!$B$2:$B$2824,vo_1111!$R$2:$R$2824,ifs!$A7,vo_1111!$H$2:$H$2824,ifs!$B7) -> 10308 | D7: =AVERAGEIFS(vo_1111!$B$2:$B$2824,vo_1111!$R$2:$R$2824,ifs!$A7,vo_1111!$H$2:$H$2824,ifs!$B7) -> 30.317647 | E7: =COUNTIFS(vo_1111!$R$2:$R$2824,ifs!$A7,vo_1111!$H$2:$H$2824,ifs!$B7) -> 340 | F7: Classic Cars | G7: Small | H7: =SUMIFS(vo_1111!$B$2:$B$2824,vo_1111!$H$2:$H$2824,ifs!$F7,vo_1111!$R$2:$R$2824,ifs!$G7) -> 10308 | I7: =AVERAGEIFS(vo_1111!$B$2:$B$2824,vo_1111!$H$2:$H$2824,ifs!$F7,vo_1111!$R$2:$R$2824,ifs!$G7) -> 30.317647 | J7: =COUNTIFS(vo_1111!$H$2:$H$2824,ifs!$F7,vo_1111!$R$2:$R$2824,ifs!$G7) -> 340
A8: Medium | B8: Trucks and Buses | C8: =SUMIFS(vo_1111!$B$2:$B$2824,vo_1111!$R$2:$R$2824,ifs!$A8,vo_1111!$H$2:$H$2824,ifs!$B8) -> 6777 | D8: =AVERAGEIFS(vo_1111!$B$2:$B$2824,vo_1111!$R$2:$R$2824,ifs!$A8,vo_1111!$H$2:$H$2824,ifs!$B8) -> 38.725714 | E8: =COUNTIFS(vo_1111!$R$2:$R$2824,ifs!$A8,vo_1111!$H$2:$H$2824,ifs!$B8) -> 175 | F8: Trucks and Buses | G8: Medium | H8: =SUMIFS(vo_1111!$B$2:$B$2824,vo_1111!$H$2:$H$2824,ifs!$F8,vo_1111!$R$2:$R$2824,ifs!$G8) -> 6777 | I8: =AVERAGEIFS(vo_1111!$B$2:$B$2824,vo_1111!$H$2:$H$2824,ifs!$F8,vo_1111!$R$2:$R$2824,ifs!$G8) -> 38.725714 | J8: =COUNTIFS(vo_1111!$H$2:$H$2824,ifs!$F8,vo_1111!$R$2:$R$2824,ifs!$G8) -> 175
A9: Small | B9: Trucks and Buses | C9: =SUMIFS(vo_1111!$B$2:$B$2824,vo_1111!$R$2:$R$2824,ifs!$A9,vo_1111!$H$2:$H$2824,ifs!$B9) -> 3642 | D9: =AVERAGEIFS(vo_1111!$B$2:$B$2824,vo_1111!$R$2:$R$2824,ifs!$A9,vo_1111!$H$2:$H$2824,ifs!$B9) -> 30.605042 | E9: =COUNTIFS(vo_1111!$R$2:$R$2824,ifs!$A9,vo_1111!$H$2:$H$2824,ifs!$B9) -> 119 | F9: Trucks and Buses | G9: Small | H9: =SUMIFS(vo_1111!$B$2:$B$2824,vo_1111!$H$2:$H$2824,ifs!$F9,vo_1111!$R$2:$R$2824,ifs!$G9) -> 3642 | I9: =AVERAGEIFS(vo_1111!$B$2:$B$2824,vo_1111!$H$2:$H$2824,ifs!$F9,vo_1111!$R$2:$R$2824,ifs!$G9) -> 30.605042 | J9: =COUNTIFS(vo_1111!$H$2:$H$2824,ifs!$F9,vo_1111!$R$2:$R$2824,ifs!$G9) -> 119
A10: Large | B10: Trucks and Buses | C10: =SUMIFS(vo_1111!$B$2:$B$2824,vo_1111!$R$2:$R$2824,ifs!$A10,vo_1111!$H$2:$H$2824,ifs!$B10) -> 358 | D10: =AVERAGEIFS(vo_1111!$B$2:$B$2824,vo_1111!$R$2:$R$2824,ifs!$A10,vo_1111!$H$2:$H$2824,ifs!$B10) -> 51.142857 | E10: =COUNTIFS(vo_1111!$R$2:$R$2824,ifs!$A10,vo_1111!$H$2:$H$2824,ifs!$B10) -> 7 | F10: Trucks and Buses | G10: Large | H10: =SUMIFS(vo_1111!$B$2:$B$2824,vo_1111!$H$2:$H$2824,ifs!$F10,vo_1111!$R$2:$R$2824,ifs!$G10) -> 358 | I10: =AVERAGEIFS(vo_1111!$B$2:$B$2824,vo_1111!$H$2:$H$2824,ifs!$F10,vo_1111!$R$2:$R$2824,ifs!$G10) -> 51.142857 | J10: =COUNTIFS(vo_1111!$H$2:$H$2824,ifs!$F10,vo_1111!$R$2:$R$2824,ifs!$G10) -> 7
A11: Medium | B11: Vintage Cars | C11: =SUMIFS(vo_1111!$B$2:$B$2824,vo_1111!$R$2:$R$2824,ifs!$A11,vo_1111!$H$2:$H$2824,ifs!$B11) -> 10022 | D11: =AVERAGEIFS(vo_1111!$B$2:$B$2824,vo_1111!$R$2:$R$2824,ifs!$A11,vo_1111!$H$2:$H$2824,ifs!$B11) -> 38.398467 | E11: =COUNTIFS(vo_1111!$R$2:$R$2824,ifs!$A11,vo_1111!$H$2:$H$2824,ifs!$B11) -> 261 | F11: Vintage Cars | G11: Medium | H11: =SUMIFS(vo_1111!$B$2:$B$2824,vo_1111!$H$2:$H$2824,ifs!$F11,vo_1111!$R$2:$R$2824,ifs!$G11) -> 10022 | I11: =AVERAGEIFS(vo_1111!$B$2:$B$2824,vo_1111!$H$2:$H$2824,ifs!$F11,vo_1111!$R$2:$R$2824,ifs!$G11) -> 38.398467 | J11: =COUNTIFS(vo_1111!$H$2:$H$2824,ifs!$F11,vo_1111!$R$2:$R$2824,ifs!$G11) -> 261
A12: Small | B12: Vintage Cars | C12: =SUMIFS(vo_1111!$B$2:$B$2824,vo_1111!$R$2:$R$2824,ifs!$A12,vo_1111!$H$2:$H$2824,ifs!$B12) -> 9935 | D12: =AVERAGEIFS(vo_1111!$B$2:$B$2824,vo_1111!$R$2:$R$2824,ifs!$A12,vo_1111!$H$2:$H$2824,ifs!$B12) -> 30.854037 | E12: =COUNTIFS(vo_1111!$R$2:$R$2824,ifs!$A12,vo_1111!$H$2:$H$2824,ifs!$B12) -> 322 | F12: Vintage Cars | G12: Small | H12: =SUMIFS(vo_1111!$B$2:$B$2824,vo_1111!$H$2:$H$2824,ifs!$F12,vo_1111!$R$2:$R$2824,ifs!$G12) -> 9935 | I12: =AVERAGEIFS(vo_1111!$B$2:$B$2824,vo_1111!$H$2:$H$2824,ifs!$F12,vo_1111!$R$2:$R$2824,ifs!$G12) -> 30.854037 | J12: =COUNTIFS(vo_1111!$H$2:$H$2824,ifs!$F12,vo_1111!$R$2:$R$2824,ifs!$G12) -> 322
A13: Large | B13: Vintage Cars | C13: =SUMIFS(vo_1111!$B$2:$B$2824,vo_1111!$R$2:$R$2824,ifs!$A13,vo_1111!$H$2:$H$2824,ifs!$B13) -> 1112 | D13: =AVERAGEIFS(vo_1111!$B$2:$B$2824,vo_1111!$R$2:$R$2824,ifs!$A13,vo_1111!$H$2:$H$2824,ifs!$B13) -> 46.333333 | E13: =COUNTIFS(vo_1111!$R$2:$R$2824,ifs!$A13,vo_1111!$H$2:$H$2824,ifs!$B13) -> 24 | F13: Vintage Cars | G13: Large | H13: =SUMIFS(vo_1111!$B$2:$B$2824,vo_1111!$H$2:$H$2824,ifs!$F13,vo_1111!$R$2:$R$2824,ifs!$G13) -> 1112 | I13: =AVERAGEIFS(vo_1111!$B$2:$B$2824,vo_1111!$H$2:$H$2824,ifs!$F13,vo_1111!$R$2:$R$2824,ifs!$G13) -> 46.333333 | J13: =COUNTIFS(vo_1111!$H$2:$H$2824,ifs!$F13,vo_1111!$R$2:$R$2824,ifs!$G13) -> 24
A14: Medium | B14: Planes | C14: =SUMIFS(vo_1111!$B$2:$B$2824,vo_1111!$R$2:$R$2824,ifs!$A14,vo_1111!$H$2:$H$2824,ifs!$B14) -> 5250 | D14: =AVERAGEIFS(vo_1111!$B$2:$B$2824,vo_1111!$R$2:$R$2824,ifs!$A14,vo_1111!$H$2:$H$2824,ifs!$B14) -> 40.697674 | E14: =COUNTIFS(vo_1111!$R$2:$R$2824,ifs!$A14,vo_1111!$H$2:$H$2824,ifs!$B14) -> 129 | F14: Planes | G14: Medium | H14: =SUMIFS(vo_1111!$B$2:$B$2824,vo_1111!$H$2:$H$2824,ifs!$F14,vo_1111!$R$2:$R$2824,ifs!$G14) -> 5250 | I14: =AVERAGEIFS(vo_1111!$B$2:$B$2824,vo_1111!$H$2:$H$2824,ifs!$F14,vo_1111!$R$2:$R$2824,ifs!$G14) -> 40.697674 | J14: =COUNTIFS(vo_1111!$H$2:$H$2824,ifs!$F14,vo_1111!$R$2:$R$2824,ifs!$G14) -> 129
A15: Small | B15: Planes | C15: =SUMIFS(vo_1111!$B$2:$B$2824,vo_1111!$R$2:$R$2824,ifs!$A15,vo_1111!$H$2:$H$2824,ifs!$B15) -> 5000 | D15: =AVERAGEIFS(vo_1111!$B$2:$B$2824,vo_1111!$R$2:$R$2824,ifs!$A15,vo_1111!$H$2:$H$2824,ifs!$B15) -> 29.761905 | E15: =COUNTIFS(vo_1111!$R$2:$R$2824,ifs!$A15,vo_1111!$H$2:$H$2824,ifs!$B15) -> 168 | F15: Planes | G15: Small | H15: =SUMIFS(vo_1111!$B$2:$B$2824,vo_1111!$H$2:$H$2824,ifs!$F15,vo_1111!$R$2:$R$2824,ifs!$G15) -> 5000 | I15: =AVERAGEIFS(vo_1111!$B$2:$B$2824,vo_1111!$H$2:$H$2824,ifs!$F15,vo_1111!$R$2:$R$2824,ifs!$G15) -> 29.761905 | J15: =COUNTIFS(vo_1111!$H$2:$H$2824,ifs!$F15,vo_1111!$R$2:$R$2824,ifs!$G15) -> 168
A16: Large | B16: Planes | C16: =SUMIFS(vo_1111!$B$2:$B$2824,vo_1111!$R$2:$R$2824,ifs!$A16,vo_1111!$H$2:$H$2824,ifs!$B16) -> 477 | D16: =AVERAGEIFS(vo_1111!$B$2:$B$2824,vo_1111!$R$2:$R$2824,ifs!$A16,vo_1111!$H$2:$H$2824,ifs!$B16) -> 53 | E16: =COUNTIFS(vo_1111!$R$2:$R$2824,ifs!$A16,vo_1111!$H$2:$H$2824,ifs!$B16) -> 9 | F16: Planes | G16: Large | H16: =SUMIFS(vo_1111!$B$2:$B$2824,vo_1111!$H$2:$H$2824,ifs!$F16,vo_1111!$R$2:$R$2824,ifs!$G16) -> 477 | I16: =AVERAGEIFS(vo_1111!$B$2:$B$2824,vo_1111!$H$2:$H$2824,ifs!$F16,vo_1111!$R$2:$R$2824,ifs!$G16) -> 53 | J16: =COUNTIFS(vo_1111!$H$2:$H$2824,ifs!$F16,vo_1111!$R$2:$R$2824,ifs!$G16) -> 9
... A21: Large | B21: Trains | C21: =SUMIFS(vo_1111!$B$2:$B$2824,vo_1111!$R$2:$R$2824,ifs!$A21,vo_1111!$H$2:$H$2824,ifs!$B21) -> 45 | D21: =AVERAGEIFS(vo_1111!$B$2:$B$2824,vo_1111!$R$2:$R$2824,ifs!$A21,vo_1111!$H$2:$H$2824,ifs!$B21) -> 45 | E21: =COUNTIFS(vo_1111!$R$2:$R$2824,ifs!$A21,vo_1111!$H$2:$H$2824,ifs!$B21) -> 1 | F21: Trains | G21: Large | H21: =SUMIFS(vo_1111!$B$2:$B$2824,vo_1111!$H$2:$H$2824,ifs!$F21,vo_1111!$R$2:$R$2824,ifs!$G21) -> 45 | I21: =AVERAGEIFS(vo_1111!$B$2:$B$2824,vo_1111!$H$2:$H$2824,ifs!$F21,vo_1111!$R$2:$R$2824,ifs!$G21) -> 45 | J21: =COUNTIFS(vo_1111!$H$2:$H$2824,ifs!$F21,vo_1111!$R$2:$R$2824,ifs!$G21) -> 1

Sheet ifs_2
A1: STATUS | B1: DEALSIZE | C1: total qty | D1: avg qty | E1: count orders
A2: Shipped | B2: Small | C2: =SUMIFS(vo_1111!$B$2:$B$2824,vo_1111!$G$2:$G$2824,ifs_2!$A2,vo_1111!$R$2:$R$2824,ifs_2!$B2) -> 36637 | D2: =AVERAGEIFS(vo_1111!$B$2:$B$2824,vo_1111!$G$2:$G$2824,ifs_2!$A2,vo_1111!$R$2:$R$2824,ifs_2!$B2) -> 30.632943 | E2: =COUNTIFS(vo_1111!$G$2:$G$2824,ifs_2!$A2,vo_1111!$R$2:$R$2824,ifs_2!$B2) -> 1196
A3: Shipped | B3: Medium | C3: =SUMIFS(vo_1111!$B$2:$B$2824,vo_1111!$G$2:$G$2824,ifs_2!$A3,vo_1111!$R$2:$R$2824,ifs_2!$B3) -> 48219 | D3: =AVERAGEIFS(vo_1111!$B$2:$B$2824,vo_1111!$G$2:$G$2824,ifs_2!$A3,vo_1111!$R$2:$R$2824,ifs_2!$B3) -> 37.730047 | E3: =COUNTIFS(vo_1111!$G$2:$G$2824,ifs_2!$A3,vo_1111!$R$2:$R$2824,ifs_2!$B3) -> 1278
A4: Shipped | B4: Large | C4: =SUMIFS(vo_1111!$B$2:$B$2824,vo_1111!$G$2:$G$2824,ifs_2!$A4,vo_1111!$R$2:$R$2824,ifs_2!$B4) -> 6547 | D4: =AVERAGEIFS(vo_1111!$B$2:$B$2824,vo_1111!$G$2:$G$2824,ifs_2!$A4,vo_1111!$R$2:$R$2824,ifs_2!$B4) -> 45.783217 | E4: =COUNTIFS(vo_1111!$G$2:$G$2824,ifs_2!$A4,vo_1111!$R$2:$R$2824,ifs_2!$B4) -> 143
A5: Disputed | B5: Large | C5: =SUMIFS(vo_1111!$B$2:$B$2824,vo_1111!$G$2:$G$2824,ifs_2!$A5,vo_1111!$R$2:$R$2824,ifs_2!$B5) -> 296 | D5: =AVERAGEIFS(vo_1111!$B$2:$B$2824,vo_1111!$G$2:$G$2824,ifs_2!$A5,vo_1111!$R$2:$R$2824,ifs_2!$B5) -> 59.2 | E5: =COUNTIFS(vo_1111!$G$2:$G$2824,ifs_2!$A5,vo_1111!$R$2:$R$2824,ifs_2!$B5) -> 5
A6: In Process | B6: Large | C6: =SUMIFS(vo_1111!$B$2:$B$2824,vo_1111!$G$2:$G$2824,ifs_2!$A6,vo_1111!$R$2:$R$2824,ifs_2!$B6) -> 153 | D6: =AVERAGEIFS(vo_1111!$B$2:$B$2824,vo_1111!$G$2:$G$2824,ifs_2!$A6,vo_1111!$R$2:$R$2824,ifs_2!$B6) -> 51 | E6: =COUNTIFS(vo_1111!$G$2:$G$2824,ifs_2!$A6,vo_1111!$R$2:$R$2824,ifs_2!$B6) -> 3
A7: Disputed | B7: Medium | C7: =SUMIFS(vo_1111!$B$2:$B$2824,vo_1111!$G$2:$G$2824,ifs_2!$A7,vo_1111!$R$2:$R$2824,ifs_2!$B7) -> 184 | D7: =AVERAGEIFS(vo_1111!$B$2:$B$2824,vo_1111!$G$2:$G$2824,ifs_2!$A7,vo_1111!$R$2:$R$2824,ifs_2!$B7) -> 36.8 | E7: =COUNTIFS(vo_1111!$G$2:$G$2824,ifs_2!$A7,vo_1111!$R$2:$R$2824,ifs_2!$B7) -> 5
A8: Cancelled | B8: Medium | C8: =SUMIFS(vo_1111!$B$2:$B$2824,vo_1111!$G$2:$G$2824,ifs_2!$A8,vo_1111!$R$2:$R$2824,ifs_2!$B8) -> 1247 | D8: =AVERAGEIFS(vo_1111!$B$2:$B$2824,vo_1111!$G$2:$G$2824,ifs_2!$A8,vo_1111!$R$2:$R$2824,ifs_2!$B8) -> 37.787879 | E8: =COUNTIFS(vo_1111!$G$2:$G$2824,ifs_2!$A8,vo_1111!$R$2:$R$2824,ifs_2!$B8) -> 33
A9: Cancelled | B9: Small | C9: =SUMIFS(vo_1111!$B$2:$B$2824,vo_1111!$G$2:$G$2824,ifs_2!$A9,vo_1111!$R$2:$R$2824,ifs_2!$B9) -> 791 | D9: =AVERAGEIFS(vo_1111!$B$2:$B$2824,vo_1111!$G$2:$G$2824,ifs_2!$A9,vo_1111!$R$2:$R$2824,ifs_2!$B9) -> 29.296296 | E9: =COUNTIFS(vo_1111!$G$2:$G$2824,ifs_2!$A9,vo_1111!$R$2:$R$2824,ifs_2!$B9) -> 27
A10: On Hold | B10: Small | C10: =SUMIFS(vo_1111!$B$2:$B$2824,vo_1111!$G$2:$G$2824,ifs_2!$A10,vo_1111!$R$2:$R$2824,ifs_2!$B10) -> 409 | D10: =AVERAGEIFS(vo_1111!$B$2:$B$2824,vo_1111!$G$2:$G$2824,ifs_2!$A10,vo_1111!$R$2:$R$2824,ifs_2!$B10) -> 27.266667 | E10: =COUNTIFS(vo_1111!$G$2:$G$2824,ifs_2!$A10,vo_1111!$R$2:$R$2824,ifs_2!$B10) -> 15
A11: Resolved | B11: Medium | C11: =SUMIFS(vo_1111!$B$2:$B$2824,vo_1111!$G$2:$G$2824,ifs_2!$A11,vo_1111!$R$2:$R$2824,ifs_2!$B11) -> 1010 | D11: =AVERAGEIFS(vo_1111!$B$2:$B$2824,vo_1111!$G$2:$G$2824,ifs_2!$A11,vo_1111!$R$2:$R$2824,ifs_2!$B11) -> 38.846154 | E11: =COUNTIFS(vo_1111!$G$2:$G$2824,ifs_2!$A11,vo_1111!$R$2:$R$2824,ifs_2!$B11) -> 26
A12: On Hold | B12: Medium | C12: =SUMIFS(vo_1111!$B$2:$B$2824,vo_1111!$G$2:$G$2824,ifs_2!$A12,vo_1111!$R$2:$R$2824,ifs_2!$B12) -> 1097 | D12: =AVERAGEIFS(vo_1111!$B$2:$B$2824,vo_1111!$G$2:$G$2824,ifs_2!$A12,vo_1111!$R$2:$R$2824,ifs_2!$B12) -> 45.708333 | E12: =COUNTIFS(vo_1111!$G$2:$G$2824,ifs_2!$A12,vo_1111!$R$2:$R$2824,ifs_2!$B12) -> 24
A13: In Process | B13: Medium | C13: =SUMIFS(vo_1111!$B$2:$B$2824,vo_1111!$G$2:$G$2824,ifs_2!$A13,vo_1111!$R$2:$R$2824,ifs_2!$B13) -> 762 | D13: =AVERAGEIFS(vo_1111!$B$2:$B$2824,vo_1111!$G$2:$G$2824,ifs_2!$A13,vo_1111!$R$2:$R$2824,ifs_2!$B13) -> 42.333333 | E13: =COUNTIFS(vo_1111!$G$2:$G$2824,ifs_2!$A13,vo_1111!$R$2:$R$2824,ifs_2!$B13) -> 18
... A18: Disputed | B18: Small | C18: =SUMIFS(vo_1111!$B$2:$B$2824,vo_1111!$G$2:$G$2824,ifs_2!$A18,vo_1111!$R$2:$R$2824,ifs_2!$B18) -> 117 | D18: =AVERAGEIFS(vo_1111!$B$2:$B$2824,vo_1111!$G$2:$G$2824,ifs_2!$A18,vo_1111!$R$2:$R$2824,ifs_2!$B18) -> 29.25 | E18: =COUNTIFS(vo_1111!$G$2:$G$2824,ifs_2!$A18,vo_1111!$R$2:$R$2824,ifs_2!$B18) -> 4

Sheet Sheet10
B2: sum | E2: sumifs
B3: average | E3: averageifs
B4: sumif | E4: countifs
B5: averageif
B6: min
B7: max
B8: count
B9: countif
B10: countblank
B11: counta
B12: sumproduct
B13: referencing
B14: bar charts
B15: column charts
B16: pie charts
B17: line charts

Sheet Sheet5
A3: Row Labels | B3: Sum of Sales
A4: Classic Cars | B4: 0.35804932
A5: Motorcycles | B5: 0.11712695
A6: Planes | B6: 0.10589244
A7: Ships | B7: 0.081769347
A8: Trains | B8: 0.02458172
A9: Trucks and Buses | B9: 0.11426464
A10: Vintage Cars | B10: 0.19831558
A11: Grand Total | B11: 1

Sheet Sheet6
A3: Row Labels | B3: Count of sno
A4: Classic Cars | B4: 967
A5: Motorcycles | B5: 331
A6: Planes | B6: 306
A7: Ships | B7: 234
A8: Trains | B8: 77
A9: Trucks and Buses | B9: 301
A10: Vintage Cars | B10: 607
A11: Grand Total | B11: 2823

Sheet Sheet7
A1: product line | B1: count
A2: Classic Cars | B2: 967
A3: Motorcycles | B3: 331
A4: Planes | B4: 306
A5: Ships | B5: 234
A6: Trains | B6: 77
A7: Trucks and Buses | B7: 301
A8: Vintage Cars | B8: 607

Sheet Sheet4
A1: sno | B1: QUANTITYORDERED | C1: PRICEEACH | D1: Sales | E1: PRODUCTLINE
A2: 1 | B2: 30 | C2: 95.7 | D2: =B2*C2 -> 2871 | E2: Motorcycles
A3: 2 | B3: 34 | C3: 81.35 | D3: =B3*C3 -> 2765.9 | E3: Motorcycles
A4: 3 | B4: 41 | C4: 94.74 | D4: =B4*C4 -> 3884.34 | E4: Motorcycles | N4: total sales
A5: 4 | B5: 45 | C5: 83.26 | D5: =B5*C5 -> 3746.7 | E5: Motorcycles | N5: =SUM(D2:D2824) -> 8290886.8
A6: 5 | B6: 49 | C6: 100 | D6: =B6*C6 -> 4900 | E6: Motorcycles
A7: 6 | B7: 36 | C7: 96.66 | D7: =B7*C7 -> 3479.76 | E7: Motorcycles
A8: 7 | B8: 29 | C8: 86.13 | D8: =B8*C8 -> 2497.77 | E8: Motorcycles
A9: 8 | B9: 48 | C9: 100 | D9: =B9*C9 -> 4800 | E9: Motorcycles
A10: 9 | B10: 22 | C10: 98.57 | D10: =B10*C10 -> 2168.54 | E10: Motorcycles
A11: 10 | B11: 41 | C11: 100 | D11: =B11*C11 -> 4100 | E11: Motorcycles
A12: 11 | B12: 37 | C12: 100 | D12: =B12*C12 -> 3700 | E12: Motorcycles
A13: 12 | B13: 23 | C13: 100 | D13: =B13*C13 -> 2300 | E13: Motorcycles
A14: 13 | B14: 28 | C14: 100 | D14: =B14*C14 -> 2800 | E14: Motorcycles
A15: 14 | B15: 34 | C15: 100 | D15: =B15*C15 -> 3400 | E15: Motorcycles
A16: 15 | B16: 45 | C16: 92.83 | D16: =B16*C16 -> 4177.35 | E16: Motorcycles
A17: 16 | B17: 36 | C17: 100 | D17: =B17*C17 -> 3600 | E17: Motorcycles
... A2824: 2823 | B2824: 47 | C2824: 65.52 | D2824: =B2824*C2824 -> 3079.44 | E2824: Ships

Sheet Sheet8
A1: QUANTITYORDERED | B1: Sales
A2: 30 | B2: 2871
A3: 34 | B3: 2765.9
A4: 41 | B4: 3884.34
A5: 45 | B5: 3746.7
A6: 49 | B6: 4900
A7: 36 | B7: 3479.76
A8: 29 | B8: 2497.77
A9: 48 | B9: 4800
A10: 22 | B10: 2168.54
A11: 41 | B11: 4100
A12: 37 | B12: 3700
A13: 23 | B13: 2300
... A2824: 47 | B2824: 3079.44

Sheet Sheet9
B4: EID | C4: ENAME | D4: SALES19 | E4: SALES20 | F4: SALES21 | H4: Sales | I4: g
B5: 1 | C5: a | D5: 10 | E5: 110 | F5: 210 | H5: SALES19 | I5: =INDEX($B$4:$F$14,MATCH($I$4,$C$4:$C$14,0),MATCH(H5,$B$4:$F$4,0)) -> 80
B6: 2 | C6: b | D6: 20 | E6: 160 | F6: 200 | H6: SALES20 | I6: =INDEX($B$4:$F$14,MATCH($I$4,$C$4:$C$14,0),MATCH(H6,$B$4:$F$4,0)) -> 120
B7: 3 | C7: c | D7: 30 | E7: 150 | F7: 190 | H7: SALES21 | I7: =INDEX($B$4:$F$14,MATCH($I$4,$C$4:$C$14,0),MATCH(H7,$B$4:$F$4,0)) -> 240
B8: 4 | C8: d | D8: 40 | E8: 140 | F8: 220
B9: 5 | C9: e | D9: 50 | E9: 120 | F9: 222
B10: 6 | C10: f | D10: 60 | E10: 130 | F10: 230
B11: 7 | C11: g | D11: 80 | E11: 120 | F11: 240
B12: 8 | C12: h | D12: 90 | E12: 110 | F12: 250
B13: 9 | C13: i | D13: 70 | E13: 150 | F13: 210
B14: 10 | C14: j | D14: 100 | E14: 190 | F14: 230

Sheet Sheet2
D2: basic text functions: | L2: find out position of e
D3: len | L3: find | M3: search
D4: trim | K4: Excel | L4: 4 | M4: 1
C5: 5 | D5: upper | K5: Excel | L5: =FIND("e",K5) -> 4 | M5: =SEARCH("e",K5) -> 1
D6: lower
D7: proper | J7: full name | K7: first name | L7: last name
J8: physics wallah | K8: =LEFT(J8,7) -> physics | L8: =RIGHT(J8,6) -> wallah
D9: extract text functions: | J9: bansal classes | K9: =LEFT(J9,7) -> bansal | L9: =RIGHT(J9,6) -> lasses
D10: left
C11: 3 | D11: right | J11: physics wallah | K11: =LEFT(J11,FIND(" ",J11)-1) -> physics | L11: =RIGHT(J11,LEN(J11)-FIND(" ",J11)) -> wallah
D12: mid | J12: bansal classes | K12: =LEFT(J12,FIND(" ",J12)-1) -> bansal | L12: =RIGHT(J12,LEN(J12)-FIND(" ",J12)) -> classes
D14: finding position:
C15: 2 | D15: find | E15: case sensitive
D16: search | E16: not case sensitive
D18: replace or join text
D19: replace
C20: 4 | D20: substitute
D21: concat
D22: &
D24: replace
D25: physics wallah | F25: =REPLACE(D25,1,7,"maths") -> maths wallah
F26: =REPLACE(D25,9,6,"point") -> physics point
D28: substitute
D29: =SUBSTITUTE(D25,"physics","maths") -> maths wallah
D30: =SUBSTITUTE(D25,"wallah","point") -> physics point

Sheet Sheet3
F4: visualisations
F5: histogram
F6: pie chart
F7: bar chart
F8: column chart
F9: scatter plot
F10: box plot
F12: histogram
F13: 1. column | G13: numerical continuous
F14: marks, height, weight, age, bmi, price etc
F15: to see the distribution
F16: normal | G16: bell shaped curve, symmetric around mean
F17: skewed | G17: left
G18: right
F20: marks
F21: 100 students
F23: 2. pie chart/donut chart
F24: % contribution
F26: super store
F27: total sales | G27: 1000
F28: sections contributed how much towards total?
F29: veggies
F30: fruits
F31: groceries
F32: household items
F33: stationary
F34: etc
F36: veggies | G36: 200 | H36: 1000 | I36: =G36/H36 -> 0.2
F37: fruits | G37: 400 | H37: 1000 | I37: =G37/H37 -> 0.4
F38: stationary | G38: 100 | H38: 1000 | I38: =G38/H38 -> 0.1
F39: groceries | G39: 50 | H39: 1000 | I39: =G39/H39 -> 0.05
F40: dairy | G40: 250 | H40: 1000 | I40: =G40/H40 -> 0.25
F42: bar chart/column chart
F43: bar chart | H43: horizontal
F44: column chart | H44: vertical
F46: objective
F48: sid | G48: subject (optional)
F49: 1 | G49: maths
F50: 2 | G50: physics
F51: 3 | G51: chemistry
...

Sheet Vlookup
A1: TABLE 1 | I1: TABLE 2
A2: EMPLOYEE ID | B2: LAST_NAME | C2: FIRST_NAME | D2: Pay | I2: EMPLOYEE ID | J2: PAY | K2: First_name | L2: Last_name
A3: 110608 | B3: Doe | C3: John | D3: =VLOOKUP($A3,$I$2:$J$15,2,FALSE) -> 131505 | I3: 990678 | J3: 84289 | K3: =VLOOKUP($I3,$A$2:$C$15,3,FALSE) -> Brad | L3: =VLOOKUP($I3,$A$2:$C$15,2,FALSE) -> Pitt
A4: 253072 | B4: Cline | C4: Andy | D4: =VLOOKUP($A4,$I$2:$J$15,2,FALSE) -> 149946 | I4: 830385 | J4: 137670 | K4: =VLOOKUP($I4,$A$2:$C$15,3,FALSE) -> Price | L4: =VLOOKUP($I4,$A$2:$C$15,2,FALSE) -> Williams
A5: 352711 | B5: Smith | C5: John | D5: =VLOOKUP($A5,$I$2:$J$15,2,FALSE) -> 89627 | I5: 795574 | J5: 190024 | K5: =VLOOKUP($I5,$A$2:$C$15,3,FALSE) -> Tony | L5: =VLOOKUP($I5,$A$2:$C$15,2,FALSE) -> Stark
A6: 391006 | B6: Pan | C6: Peter | D6: =VLOOKUP($A6,$I$2:$J$15,2,FALSE) -> 168114 | I6: 580622 | J6: 122604 | K6: =VLOOKUP($I6,$A$2:$C$15,3,FALSE) -> Eli | L6: =VLOOKUP($I6,$A$2:$C$15,2,FALSE) -> Manning
A7: 392128 | B7: Fawre | C7: Bret | D7: =VLOOKUP($A7,$I$2:$J$15,2,FALSE) -> 85931 | I7: 549427 | J7: 111700 | K7: =VLOOKUP($I7,$A$2:$C$15,3,FALSE) -> John | L7: =VLOOKUP($I7,$A$2:$C$15,2,FALSE) -> Elway
A8: 549427 | B8: Elway | C8: John | D8: =VLOOKUP($A8,$I$2:$J$15,2,FALSE) -> 111700 | I8: 392128 | J8: 85931 | K8: =VLOOKUP($I8,$A$2:$C$15,3,FALSE) -> Bret | L8: =VLOOKUP($I8,$A$2:$C$15,2,FALSE) -> Fawre
A9: 580622 | B9: Manning | C9: Eli | D9: =VLOOKUP($A9,$I$2:$J$15,2,FALSE) -> 122604 | I9: 391006 | J9: 168114 | K9: =VLOOKUP($I9,$A$2:$C$15,3,FALSE) -> Peter | L9: =VLOOKUP($I9,$A$2:$C$15,2,FALSE) -> Pan
A10: 602693 | B10: Vick | C10: Micheal | D10: =VLOOKUP($A10,$I$2:$J$15,2,FALSE) -> 71478 | I10: 352711 | J10: 89627 | K10: =VLOOKUP($I10,$A$2:$C$15,3,FALSE) -> John | L10: =VLOOKUP($I10,$A$2:$C$15,2,FALSE) -> Smith
A11: 611810 | B11: Woods | C11: Tiger | D11: =VLOOKUP($A11,$I$2:$J$15,2,FALSE) -> 64757 | I11: 253072 | J11: 149946 | K11: =VLOOKUP($I11,$A$2:$C$15,3,FALSE) -> Andy | L11: =VLOOKUP($I11,$A$2:$C$15,2,FALSE) -> Cline
A12: 612235 | B12: Jordan | C12: Micheal | D12: =VLOOKUP($A12,$I$2:$J$15,2,FALSE) -> 145893 | I12: 612235 | J12: 145893 | K12: =VLOOKUP($I12,$A$2:$C$15,3,FALSE) -> Micheal | L12: =VLOOKUP($I12,$A$2:$C$15,2,FALSE) -> Jordan
A13: 795574 | B13: Stark | C13: Tony | D13: =VLOOKUP($A13,$I$2:$J$15,2,FALSE) -> 190024 | I13: 611810 | J13: 64757 | K13: =VLOOKUP($I13,$A$2:$C$15,3,FALSE) -> Tiger | L13: =VLOOKUP($I13,$A$2:$C$15,2,FALSE) -> Woods
A14: 830385 | B14: Williams | C14: Price | D14: =VLOOKUP($A14,$I$2:$J$15,2,FALSE) -> 137670 | I14: 602693 | J14: 71478 | K14: =VLOOKUP($I14,$A$2:$C$15,3,FALSE) -> Micheal | L14: =VLOOKUP($I14,$A$2:$C$15,2,FALSE) -> Vick
A15: 990678 | B15: Pitt | C15: Brad | D15: =VLOOKUP($A15,$I$2:$J$15,2,FALSE) -> 84289 | I15: 110608 | J15: 131505 | K15: =VLOOKUP($I15,$A$2:$C$15,3,FALSE) -> John | L15: =VLOOKUP($I15,$A$2:$C$15,2,FALSE) -> Doe
F19: Vlookup | G19: vertical lookup | I19: top to bottom | J19: to look for a value
F20: Hlookup | G20: horizontal lookup | I20: left to right
F21: Xlookup

Sheet Xlookup
A1: STUDENT NAME | B1: A | C1: B | D1: C | E1: D | F1: E
A2: ACCOUNTS | B2: 75 | C2: 65 | D2: 70 | E2: 60 | F2: 59
A3: ECONOMICS | B3: 65 | C3: 72 | D3: 78 | E3: 89 | F3: 67
A4: MANAGEMENT | B4: 70 | C4: 68 | D4: 90 | E4: 72 | F4: 58
A5: MATHEMATICS | B5: 80 | C5: 90 | D5: 75 | E5: 65 | F5: 87
A8: Marks of D in management | B8: =HLOOKUP($E1,$A$1:$F$5,4,FALSE) -> 72
A9: Marks of A in accounts | B9: =HLOOKUP($B1,$A$1:$F$5,2,FALSE) -> 75
A10: Marks of B in economics | B10: =HLOOKUP($C1,$A$1:$F$5,3,FALSE) -> 72
A11: Marks of C in mathematics | B11: =HLOOKUP($D1,$A$1:$F$5,5,FALSE) -> 75
A12: Marks of E in management | B12: =HLOOKUP($F1,$A$1:$F$5,4,FALSE) -> 58
H13: eid | I13: ename | J13: sales_1 | K13: sales_2 | L13: sales_3
H14: 101 | I14: aman | J14: 10000 | K14: 20000 | L14: 45000
H15: 102 | I15: archit | J15: 20000 | K15: 23000 | L15: 43000
H16: 103 | I16: shubham | J16: 30000 | K16: 34000 | L16: 54000
A17: sales_1 in aakash | B17: =HLOOKUP($J13,$H$13:$L$23,7,FALSE) -> 34500 | H17: 104 | I17: shreya | J17: 23000 | K17: 45000 | L17: 98000
H18: 105 | I18: riya | J18: 250000 | K18: 56000 | L18: 96000
H19: 106 | I19: aakash | J19: 34500 | K19: 67000 | L19: 65000
H20: 107 | I20: dhruv | J20: 56000 | K20: 78000 | L20: 64000
H21: 108 | I21: lipin | J21: 76000 | K21: 54000 | L21: 63000
H22: 109 | I22: nitin | J22: 89000 | K22: 87000 | L22: 85000
H23: 110 | I23: pratham | J23: 65000 | K23: 65000 | L23: 87000

Sheet Sheet1
A1: ORDERDATE | B1: ORDERTIME | C1: YEAR | D1: MONTH | E1: DAY
A2: 41623 | B2: 0.034722222 | C2: =TEXT(A2,"YY") -> 13 | D2: =TEXT(A2,"mm") -> 12 | E2: =TEXT(A2,"dd") -> 15
A3: 41758 | B3: 0.98611111 | C3: =TEXT(A3,"YY") -> 14 | D3: =TEXT(A3,"mm") -> 04 | E3: =TEXT(A3,"dd") -> 29
A4: 41273 | B4: 0.014583333 | C4: =TEXT(A4,"YY") -> 12 | D4: =TEXT(A4,"mm") -> 12 | E4: =TEXT(A4,"dd") -> 30
A5: 41971 | B5: 0.021527778 | C5: =TEXT(A5,"YY") -> 14 | D5: =TEXT(A5,"mm") -> 11 | E5: =TEXT(A5,"dd") -> 28
A6: 41573 | B6: 0.96597222 | C6: =TEXT(A6,"YY") -> 13 | D6: =TEXT(A6,"mm") -> 10 | E6: =TEXT(A6,"dd") -> 26
A7: 42437 | B7: 0.95277778 | C7: =TEXT(A7,"YY") -> 16 | D7: =TEXT(A7,"mm") -> 03 | E7: =TEXT(A7,"dd") -> 08
A8: 41688 | B8: 0.015972222 | C8: =TEXT(A8,"YY") -> 14 | D8: =TEXT(A8,"mm") -> 02 | E8: =TEXT(A8,"dd") -> 18
A9: 41236 | B9: 0.048611111 | C9: =TEXT(A9,"YY") -> 12 | D9: =TEXT(A9,"mm") -> 11 | E9: =TEXT(A9,"dd") -> 23
A10: 41996 | B10: 0.055555556 | C10: =TEXT(A10,"YY") -> 14 | D10: =TEXT(A10,"mm") -> 12 | E10: =TEXT(A10,"dd") -> 23
A11: 41216 | B11: 0.99027778 | C11: =TEXT(A11,"YY") -> 12 | D11: =TEXT(A11,"mm") -> 11 | E11: =TEXT(A11,"dd") -> 03
A12: 41481 | B12: 0.0076388889 | C12: =TEXT(A12,"YY") -> 13 | D12: =TEXT(A12,"mm") -> 07 | E12: =TEXT(A12,"dd") -> 26
A13: 41626 | B13: 0.027083333 | C13: =TEXT(A13,"YY") -> 13 | D13: =TEXT(A13,"mm") -> 12 | E13: =TEXT(A13,"dd") -> 18
... A2824: 42247 | B2824: 0.0013888889 | C2824: =TEXT(A2824,"YY") -> 15 | D2824: =TEXT(A2824,"mm") -> 08 | E2824: =TEXT(A2824,"dd") -> 31
